{
 "cells": [
  {
   "cell_type": "code",
   "execution_count": 13,
   "id": "80dc6dc4",
   "metadata": {},
   "outputs": [
    {
     "name": "stdout",
     "output_type": "stream",
     "text": [
      "ERROR! Session/line number was not unique in database. History logging moved to new session 613\n"
     ]
    }
   ],
   "source": [
    "import tensorflow as tf\n",
    "import pandas as pd\n",
    "import numpy as np\n",
    "import tensorflow as tf\n",
    "from sklearn import datasets"
   ]
  },
  {
   "cell_type": "code",
   "execution_count": 14,
   "id": "f346fb43",
   "metadata": {},
   "outputs": [],
   "source": [
    "X_data=[[1,0,1,0,1,0,0,1,0,1],[1,0,0,0,1,0,0,1,0,1],\n",
    "        [0,0,1,0,1,0,0,1,0,1],[1,0,0,0,1,0,0,1,0,1],\n",
    "       [1,0,1,0,0,0,0,1,0,1],[1,0,0,0,0,0,0,1,0,1],\n",
    "       [1,0,1,0,1,0,0,0,0,1],[1,0,0,1,0,0,0,1,0,1],\n",
    "       [1,0,1,0,1,0,0,1,0,0],[1,0,0,0,0,0,0,1,0,1],\n",
    "       [1,0,1,0,0,0,0,0,0,1],[1,1,0,0,0,0,0,1,0,1],\n",
    "       [1,0,1,0,0,0,0,1,0,1],[1,0,1,0,0,0,0,1,0,1],\n",
    "       [1,0,1,0,0,0,0,0,0,1],[1,0,0,1,0,0,0,1,0,1],\n",
    "       [1,0,0,0,1,0,0,0,0,1],[1,0,0,0,1,0,0,1,0,1],\n",
    "       [1,0,0,1,0,0,0,1,0,1],[1,0,0,0,0,1,0,1,0,1],\n",
    "       [1,0,1,0,0,0,0,1,0,1],[1,0,0,0,1,0,0,1,0,1],\n",
    "        [1,0,0,0,0,1,0,1,0,1],[1,0,0,1,0,1,0,1,0,1],\n",
    "        [1,0,0,1,0,0,0,1,0,1],[1,0,0,0,0,1,0,1,0,1],\n",
    "        [1,1,0,0,0,0,0,1,0,1],[1,0,0,0,0,1,0,1,0,1],\n",
    "        [1,0,0,1,0,0,0,1,0,1],[1,0,0,0,0,1,0,1,0,1],\n",
    "        [1,0,0,0,0,0,0,1,0,1],[1,0,0,0,0,1,0,1,0,1],\n",
    "        [1,0,0,0,0,1,0,1,0,1],[1,0,0,0,0,1,0,1,0,1],\n",
    "        [1,0,0,0,1,0,0,1,0,1],[1,0,0,1,0,0,0,1,0,1],\n",
    "        \n",
    "       ]"
   ]
  },
  {
   "cell_type": "code",
   "execution_count": 15,
   "id": "5eecf6ce",
   "metadata": {},
   "outputs": [],
   "source": [
    "y_data=[0,1,2,0,1,2,0,1,2,0]"
   ]
  },
  {
   "cell_type": "code",
   "execution_count": 16,
   "id": "6940276f",
   "metadata": {},
   "outputs": [],
   "source": [
    "y=pd.get_dummies(y_data)"
   ]
  },
  {
   "cell_type": "code",
   "execution_count": 17,
   "id": "40a3a0ad",
   "metadata": {},
   "outputs": [
    {
     "data": {
      "text/html": [
       "<div>\n",
       "<style scoped>\n",
       "    .dataframe tbody tr th:only-of-type {\n",
       "        vertical-align: middle;\n",
       "    }\n",
       "\n",
       "    .dataframe tbody tr th {\n",
       "        vertical-align: top;\n",
       "    }\n",
       "\n",
       "    .dataframe thead th {\n",
       "        text-align: right;\n",
       "    }\n",
       "</style>\n",
       "<table border=\"1\" class=\"dataframe\">\n",
       "  <thead>\n",
       "    <tr style=\"text-align: right;\">\n",
       "      <th></th>\n",
       "      <th>0</th>\n",
       "      <th>1</th>\n",
       "      <th>2</th>\n",
       "    </tr>\n",
       "  </thead>\n",
       "  <tbody>\n",
       "    <tr>\n",
       "      <th>0</th>\n",
       "      <td>1</td>\n",
       "      <td>0</td>\n",
       "      <td>0</td>\n",
       "    </tr>\n",
       "    <tr>\n",
       "      <th>1</th>\n",
       "      <td>0</td>\n",
       "      <td>1</td>\n",
       "      <td>0</td>\n",
       "    </tr>\n",
       "    <tr>\n",
       "      <th>2</th>\n",
       "      <td>0</td>\n",
       "      <td>0</td>\n",
       "      <td>1</td>\n",
       "    </tr>\n",
       "    <tr>\n",
       "      <th>3</th>\n",
       "      <td>1</td>\n",
       "      <td>0</td>\n",
       "      <td>0</td>\n",
       "    </tr>\n",
       "    <tr>\n",
       "      <th>4</th>\n",
       "      <td>0</td>\n",
       "      <td>1</td>\n",
       "      <td>0</td>\n",
       "    </tr>\n",
       "    <tr>\n",
       "      <th>5</th>\n",
       "      <td>0</td>\n",
       "      <td>0</td>\n",
       "      <td>1</td>\n",
       "    </tr>\n",
       "    <tr>\n",
       "      <th>6</th>\n",
       "      <td>1</td>\n",
       "      <td>0</td>\n",
       "      <td>0</td>\n",
       "    </tr>\n",
       "    <tr>\n",
       "      <th>7</th>\n",
       "      <td>0</td>\n",
       "      <td>1</td>\n",
       "      <td>0</td>\n",
       "    </tr>\n",
       "    <tr>\n",
       "      <th>8</th>\n",
       "      <td>0</td>\n",
       "      <td>0</td>\n",
       "      <td>1</td>\n",
       "    </tr>\n",
       "    <tr>\n",
       "      <th>9</th>\n",
       "      <td>1</td>\n",
       "      <td>0</td>\n",
       "      <td>0</td>\n",
       "    </tr>\n",
       "  </tbody>\n",
       "</table>\n",
       "</div>"
      ],
      "text/plain": [
       "   0  1  2\n",
       "0  1  0  0\n",
       "1  0  1  0\n",
       "2  0  0  1\n",
       "3  1  0  0\n",
       "4  0  1  0\n",
       "5  0  0  1\n",
       "6  1  0  0\n",
       "7  0  1  0\n",
       "8  0  0  1\n",
       "9  1  0  0"
      ]
     },
     "execution_count": 17,
     "metadata": {},
     "output_type": "execute_result"
    }
   ],
   "source": [
    "y"
   ]
  },
  {
   "cell_type": "code",
   "execution_count": 18,
   "id": "edefb2da",
   "metadata": {},
   "outputs": [
    {
     "name": "stdout",
     "output_type": "stream",
     "text": [
      "Model: \"sequential_2\"\n",
      "_________________________________________________________________\n",
      "Layer (type)                 Output Shape              Param #   \n",
      "=================================================================\n",
      "dense_6 (Dense)              (None, 20)                220       \n",
      "_________________________________________________________________\n",
      "dense_7 (Dense)              (None, 10)                210       \n",
      "_________________________________________________________________\n",
      "dense_8 (Dense)              (None, 3)                 33        \n",
      "=================================================================\n",
      "Total params: 463\n",
      "Trainable params: 463\n",
      "Non-trainable params: 0\n",
      "_________________________________________________________________\n"
     ]
    }
   ],
   "source": [
    "from tensorflow.keras.models import Sequential #신경망 생성\n",
    "from tensorflow.keras.layers import Dense #퍼셉트론으로 구성된 신경망층 정의\n",
    "from tensorflow.keras.layers import Activation\n",
    "\n",
    "model = Sequential()\n",
    "#입력층\n",
    "model.add(Dense(units=20,input_dim=10,activation = 'relu'))\n",
    "#은닉층\n",
    "model.add(Dense(units=10,activation='relu'))\n",
    "#출력층\n",
    "model.add(Dense(units=3,activation='softmax'))\n",
    "\n",
    "model.summary()\n"
   ]
  },
  {
   "cell_type": "code",
   "execution_count": 19,
   "id": "4c51ee58",
   "metadata": {},
   "outputs": [],
   "source": [
    "model.compile(loss='categorical_crossentropy',\n",
    "             optimizer='adam',\n",
    "             metrics = ['accuracy'])"
   ]
  },
  {
   "cell_type": "code",
   "execution_count": null,
   "id": "7fdb030b",
   "metadata": {},
   "outputs": [
    {
     "name": "stderr",
     "output_type": "stream",
     "text": [
      "ERROR:root:Internal Python error in the inspect module.\n",
      "Below is the traceback from this internal error.\n",
      "\n",
      "ERROR:root:Internal Python error in the inspect module.\n",
      "Below is the traceback from this internal error.\n",
      "\n",
      "ERROR:root:Internal Python error in the inspect module.\n",
      "Below is the traceback from this internal error.\n",
      "\n"
     ]
    },
    {
     "name": "stdout",
     "output_type": "stream",
     "text": [
      "Traceback (most recent call last):\n",
      "  File \"C:\\Users\\SM2127\\anaconda3\\envs\\deep01\\lib\\site-packages\\IPython\\core\\interactiveshell.py\", line 3343, in run_code\n",
      "    exec(code_obj, self.user_global_ns, self.user_ns)\n",
      "  File \"<ipython-input-20-46304c5ff6bb>\", line 1, in <module>\n",
      "    model.fit(X_data,y,epochs=100,batch_size=20,validation_split=0.25)\n",
      "  File \"C:\\Users\\SM2127\\anaconda3\\envs\\deep01\\lib\\site-packages\\tensorflow_core\\python\\keras\\engine\\training.py\", line 819, in fit\n",
      "    use_multiprocessing=use_multiprocessing)\n",
      "  File \"C:\\Users\\SM2127\\anaconda3\\envs\\deep01\\lib\\site-packages\\tensorflow_core\\python\\keras\\engine\\training_v2.py\", line 235, in fit\n",
      "    use_multiprocessing=use_multiprocessing)\n",
      "  File \"C:\\Users\\SM2127\\anaconda3\\envs\\deep01\\lib\\site-packages\\tensorflow_core\\python\\keras\\engine\\training_v2.py\", line 533, in _process_training_inputs\n",
      "    adapter_cls = data_adapter.select_data_adapter(x, y)\n",
      "  File \"C:\\Users\\SM2127\\anaconda3\\envs\\deep01\\lib\\site-packages\\tensorflow_core\\python\\keras\\engine\\data_adapter.py\", line 998, in select_data_adapter\n",
      "    _type_name(x), _type_name(y)))\n",
      "ValueError: Failed to find data adapter that can handle input: (<class 'list'> containing values of types {'(<class \\'list\\'> containing values of types {\"<class \\'int\\'>\"})'}), <class 'pandas.core.frame.DataFrame'>\n",
      "\n",
      "During handling of the above exception, another exception occurred:\n",
      "\n",
      "Traceback (most recent call last):\n",
      "  File \"C:\\Users\\SM2127\\anaconda3\\envs\\deep01\\lib\\site-packages\\IPython\\core\\interactiveshell.py\", line 2044, in showtraceback\n",
      "    stb = value._render_traceback_()\n",
      "AttributeError: 'ValueError' object has no attribute '_render_traceback_'\n",
      "\n",
      "During handling of the above exception, another exception occurred:\n",
      "\n",
      "Traceback (most recent call last):\n",
      "  File \"C:\\Users\\SM2127\\anaconda3\\envs\\deep01\\lib\\site-packages\\IPython\\core\\ultratb.py\", line 1169, in get_records\n",
      "    return _fixed_getinnerframes(etb, number_of_lines_of_context, tb_offset)\n",
      "  File \"C:\\Users\\SM2127\\anaconda3\\envs\\deep01\\lib\\site-packages\\IPython\\core\\ultratb.py\", line 316, in wrapped\n",
      "    return f(*args, **kwargs)\n",
      "  File \"C:\\Users\\SM2127\\anaconda3\\envs\\deep01\\lib\\site-packages\\IPython\\core\\ultratb.py\", line 350, in _fixed_getinnerframes\n",
      "    records = fix_frame_records_filenames(inspect.getinnerframes(etb, context))\n",
      "  File \"C:\\Users\\SM2127\\anaconda3\\envs\\deep01\\lib\\inspect.py\", line 1490, in getinnerframes\n",
      "    frameinfo = (tb.tb_frame,) + getframeinfo(tb, context)\n",
      "  File \"C:\\Users\\SM2127\\anaconda3\\envs\\deep01\\lib\\inspect.py\", line 1448, in getframeinfo\n",
      "    filename = getsourcefile(frame) or getfile(frame)\n",
      "  File \"C:\\Users\\SM2127\\anaconda3\\envs\\deep01\\lib\\inspect.py\", line 696, in getsourcefile\n",
      "    if getattr(getmodule(object, filename), '__loader__', None) is not None:\n",
      "  File \"C:\\Users\\SM2127\\anaconda3\\envs\\deep01\\lib\\inspect.py\", line 733, in getmodule\n",
      "    if ismodule(module) and hasattr(module, '__file__'):\n",
      "  File \"C:\\Users\\SM2127\\anaconda3\\envs\\deep01\\lib\\site-packages\\tensorflow\\__init__.py\", line 50, in __getattr__\n",
      "    module = self._load()\n",
      "  File \"C:\\Users\\SM2127\\anaconda3\\envs\\deep01\\lib\\site-packages\\tensorflow\\__init__.py\", line 44, in _load\n",
      "    module = _importlib.import_module(self.__name__)\n",
      "  File \"C:\\Users\\SM2127\\anaconda3\\envs\\deep01\\lib\\importlib\\__init__.py\", line 126, in import_module\n",
      "    return _bootstrap._gcd_import(name[level:], package, level)\n",
      "  File \"<frozen importlib._bootstrap>\", line 994, in _gcd_import\n",
      "  File \"<frozen importlib._bootstrap>\", line 971, in _find_and_load\n",
      "  File \"<frozen importlib._bootstrap>\", line 953, in _find_and_load_unlocked\n",
      "ModuleNotFoundError: No module named 'tensorflow_core.estimator'\n",
      "Traceback (most recent call last):\n",
      "  File \"C:\\Users\\SM2127\\anaconda3\\envs\\deep01\\lib\\site-packages\\IPython\\core\\interactiveshell.py\", line 3343, in run_code\n",
      "    exec(code_obj, self.user_global_ns, self.user_ns)\n",
      "  File \"<ipython-input-20-46304c5ff6bb>\", line 1, in <module>\n",
      "    model.fit(X_data,y,epochs=100,batch_size=20,validation_split=0.25)\n",
      "  File \"C:\\Users\\SM2127\\anaconda3\\envs\\deep01\\lib\\site-packages\\tensorflow_core\\python\\keras\\engine\\training.py\", line 819, in fit\n",
      "    use_multiprocessing=use_multiprocessing)\n",
      "  File \"C:\\Users\\SM2127\\anaconda3\\envs\\deep01\\lib\\site-packages\\tensorflow_core\\python\\keras\\engine\\training_v2.py\", line 235, in fit\n",
      "    use_multiprocessing=use_multiprocessing)\n",
      "  File \"C:\\Users\\SM2127\\anaconda3\\envs\\deep01\\lib\\site-packages\\tensorflow_core\\python\\keras\\engine\\training_v2.py\", line 533, in _process_training_inputs\n",
      "    adapter_cls = data_adapter.select_data_adapter(x, y)\n",
      "  File \"C:\\Users\\SM2127\\anaconda3\\envs\\deep01\\lib\\site-packages\\tensorflow_core\\python\\keras\\engine\\data_adapter.py\", line 998, in select_data_adapter\n",
      "    _type_name(x), _type_name(y)))\n",
      "ValueError: Failed to find data adapter that can handle input: (<class 'list'> containing values of types {'(<class \\'list\\'> containing values of types {\"<class \\'int\\'>\"})'}), <class 'pandas.core.frame.DataFrame'>\n",
      "\n",
      "During handling of the above exception, another exception occurred:\n",
      "\n",
      "Traceback (most recent call last):\n",
      "  File \"C:\\Users\\SM2127\\anaconda3\\envs\\deep01\\lib\\site-packages\\IPython\\core\\interactiveshell.py\", line 2044, in showtraceback\n",
      "    stb = value._render_traceback_()\n",
      "AttributeError: 'ValueError' object has no attribute '_render_traceback_'\n",
      "\n",
      "During handling of the above exception, another exception occurred:\n",
      "\n",
      "Traceback (most recent call last):\n",
      "  File \"C:\\Users\\SM2127\\anaconda3\\envs\\deep01\\lib\\site-packages\\IPython\\core\\interactiveshell.py\", line 3263, in run_ast_nodes\n",
      "    if (await self.run_code(code, result,  async_=asy)):\n",
      "  File \"C:\\Users\\SM2127\\anaconda3\\envs\\deep01\\lib\\site-packages\\IPython\\core\\interactiveshell.py\", line 3360, in run_code\n",
      "    self.showtraceback(running_compiled_code=True)\n",
      "  File \"C:\\Users\\SM2127\\anaconda3\\envs\\deep01\\lib\\site-packages\\IPython\\core\\interactiveshell.py\", line 2047, in showtraceback\n",
      "    value, tb, tb_offset=tb_offset)\n",
      "  File \"C:\\Users\\SM2127\\anaconda3\\envs\\deep01\\lib\\site-packages\\IPython\\core\\ultratb.py\", line 1436, in structured_traceback\n",
      "    self, etype, value, tb, tb_offset, number_of_lines_of_context)\n",
      "  File \"C:\\Users\\SM2127\\anaconda3\\envs\\deep01\\lib\\site-packages\\IPython\\core\\ultratb.py\", line 1336, in structured_traceback\n",
      "    self, etype, value, tb, tb_offset, number_of_lines_of_context\n",
      "  File \"C:\\Users\\SM2127\\anaconda3\\envs\\deep01\\lib\\site-packages\\IPython\\core\\ultratb.py\", line 1193, in structured_traceback\n",
      "    tb_offset)\n",
      "  File \"C:\\Users\\SM2127\\anaconda3\\envs\\deep01\\lib\\site-packages\\IPython\\core\\ultratb.py\", line 1150, in format_exception_as_a_whole\n",
      "    last_unique, recursion_repeat = find_recursion(orig_etype, evalue, records)\n",
      "  File \"C:\\Users\\SM2127\\anaconda3\\envs\\deep01\\lib\\site-packages\\IPython\\core\\ultratb.py\", line 451, in find_recursion\n",
      "    return len(records), 0\n",
      "TypeError: object of type 'NoneType' has no len()\n",
      "\n",
      "During handling of the above exception, another exception occurred:\n",
      "\n",
      "Traceback (most recent call last):\n",
      "  File \"C:\\Users\\SM2127\\anaconda3\\envs\\deep01\\lib\\site-packages\\IPython\\core\\interactiveshell.py\", line 2044, in showtraceback\n",
      "    stb = value._render_traceback_()\n",
      "AttributeError: 'TypeError' object has no attribute '_render_traceback_'\n",
      "\n",
      "During handling of the above exception, another exception occurred:\n",
      "\n",
      "Traceback (most recent call last):\n",
      "  File \"C:\\Users\\SM2127\\anaconda3\\envs\\deep01\\lib\\site-packages\\IPython\\core\\ultratb.py\", line 1169, in get_records\n",
      "    return _fixed_getinnerframes(etb, number_of_lines_of_context, tb_offset)\n",
      "  File \"C:\\Users\\SM2127\\anaconda3\\envs\\deep01\\lib\\site-packages\\IPython\\core\\ultratb.py\", line 316, in wrapped\n",
      "    return f(*args, **kwargs)\n",
      "  File \"C:\\Users\\SM2127\\anaconda3\\envs\\deep01\\lib\\site-packages\\IPython\\core\\ultratb.py\", line 350, in _fixed_getinnerframes\n",
      "    records = fix_frame_records_filenames(inspect.getinnerframes(etb, context))\n",
      "  File \"C:\\Users\\SM2127\\anaconda3\\envs\\deep01\\lib\\inspect.py\", line 1490, in getinnerframes\n",
      "    frameinfo = (tb.tb_frame,) + getframeinfo(tb, context)\n",
      "  File \"C:\\Users\\SM2127\\anaconda3\\envs\\deep01\\lib\\inspect.py\", line 1448, in getframeinfo\n",
      "    filename = getsourcefile(frame) or getfile(frame)\n",
      "  File \"C:\\Users\\SM2127\\anaconda3\\envs\\deep01\\lib\\inspect.py\", line 696, in getsourcefile\n",
      "    if getattr(getmodule(object, filename), '__loader__', None) is not None:\n",
      "  File \"C:\\Users\\SM2127\\anaconda3\\envs\\deep01\\lib\\inspect.py\", line 733, in getmodule\n",
      "    if ismodule(module) and hasattr(module, '__file__'):\n",
      "  File \"C:\\Users\\SM2127\\anaconda3\\envs\\deep01\\lib\\site-packages\\tensorflow\\__init__.py\", line 50, in __getattr__\n",
      "    module = self._load()\n",
      "  File \"C:\\Users\\SM2127\\anaconda3\\envs\\deep01\\lib\\site-packages\\tensorflow\\__init__.py\", line 44, in _load\n",
      "    module = _importlib.import_module(self.__name__)\n",
      "  File \"C:\\Users\\SM2127\\anaconda3\\envs\\deep01\\lib\\importlib\\__init__.py\", line 126, in import_module\n",
      "    return _bootstrap._gcd_import(name[level:], package, level)\n",
      "  File \"<frozen importlib._bootstrap>\", line 994, in _gcd_import\n",
      "  File \"<frozen importlib._bootstrap>\", line 971, in _find_and_load\n",
      "  File \"<frozen importlib._bootstrap>\", line 953, in _find_and_load_unlocked\n",
      "ModuleNotFoundError: No module named 'tensorflow_core.estimator'\n",
      "Traceback (most recent call last):\n",
      "  File \"C:\\Users\\SM2127\\anaconda3\\envs\\deep01\\lib\\site-packages\\IPython\\core\\interactiveshell.py\", line 3343, in run_code\n",
      "    exec(code_obj, self.user_global_ns, self.user_ns)\n",
      "  File \"<ipython-input-20-46304c5ff6bb>\", line 1, in <module>\n",
      "    model.fit(X_data,y,epochs=100,batch_size=20,validation_split=0.25)\n",
      "  File \"C:\\Users\\SM2127\\anaconda3\\envs\\deep01\\lib\\site-packages\\tensorflow_core\\python\\keras\\engine\\training.py\", line 819, in fit\n",
      "    use_multiprocessing=use_multiprocessing)\n",
      "  File \"C:\\Users\\SM2127\\anaconda3\\envs\\deep01\\lib\\site-packages\\tensorflow_core\\python\\keras\\engine\\training_v2.py\", line 235, in fit\n",
      "    use_multiprocessing=use_multiprocessing)\n",
      "  File \"C:\\Users\\SM2127\\anaconda3\\envs\\deep01\\lib\\site-packages\\tensorflow_core\\python\\keras\\engine\\training_v2.py\", line 533, in _process_training_inputs\n",
      "    adapter_cls = data_adapter.select_data_adapter(x, y)\n",
      "  File \"C:\\Users\\SM2127\\anaconda3\\envs\\deep01\\lib\\site-packages\\tensorflow_core\\python\\keras\\engine\\data_adapter.py\", line 998, in select_data_adapter\n",
      "    _type_name(x), _type_name(y)))\n",
      "ValueError: Failed to find data adapter that can handle input: (<class 'list'> containing values of types {'(<class \\'list\\'> containing values of types {\"<class \\'int\\'>\"})'}), <class 'pandas.core.frame.DataFrame'>\n",
      "\n",
      "During handling of the above exception, another exception occurred:\n",
      "\n",
      "Traceback (most recent call last):\n",
      "  File \"C:\\Users\\SM2127\\anaconda3\\envs\\deep01\\lib\\site-packages\\IPython\\core\\interactiveshell.py\", line 2044, in showtraceback\n",
      "    stb = value._render_traceback_()\n",
      "AttributeError: 'ValueError' object has no attribute '_render_traceback_'\n",
      "\n",
      "During handling of the above exception, another exception occurred:\n",
      "\n",
      "Traceback (most recent call last):\n",
      "  File \"C:\\Users\\SM2127\\anaconda3\\envs\\deep01\\lib\\site-packages\\IPython\\core\\interactiveshell.py\", line 3263, in run_ast_nodes\n",
      "    if (await self.run_code(code, result,  async_=asy)):\n",
      "  File \"C:\\Users\\SM2127\\anaconda3\\envs\\deep01\\lib\\site-packages\\IPython\\core\\interactiveshell.py\", line 3360, in run_code\n",
      "    self.showtraceback(running_compiled_code=True)\n",
      "  File \"C:\\Users\\SM2127\\anaconda3\\envs\\deep01\\lib\\site-packages\\IPython\\core\\interactiveshell.py\", line 2047, in showtraceback\n",
      "    value, tb, tb_offset=tb_offset)\n",
      "  File \"C:\\Users\\SM2127\\anaconda3\\envs\\deep01\\lib\\site-packages\\IPython\\core\\ultratb.py\", line 1436, in structured_traceback\n",
      "    self, etype, value, tb, tb_offset, number_of_lines_of_context)\n",
      "  File \"C:\\Users\\SM2127\\anaconda3\\envs\\deep01\\lib\\site-packages\\IPython\\core\\ultratb.py\", line 1336, in structured_traceback\n",
      "    self, etype, value, tb, tb_offset, number_of_lines_of_context\n",
      "  File \"C:\\Users\\SM2127\\anaconda3\\envs\\deep01\\lib\\site-packages\\IPython\\core\\ultratb.py\", line 1193, in structured_traceback\n",
      "    tb_offset)\n",
      "  File \"C:\\Users\\SM2127\\anaconda3\\envs\\deep01\\lib\\site-packages\\IPython\\core\\ultratb.py\", line 1150, in format_exception_as_a_whole\n",
      "    last_unique, recursion_repeat = find_recursion(orig_etype, evalue, records)\n",
      "  File \"C:\\Users\\SM2127\\anaconda3\\envs\\deep01\\lib\\site-packages\\IPython\\core\\ultratb.py\", line 451, in find_recursion\n",
      "    return len(records), 0\n",
      "TypeError: object of type 'NoneType' has no len()\n",
      "\n",
      "During handling of the above exception, another exception occurred:\n",
      "\n",
      "Traceback (most recent call last):\n",
      "  File \"C:\\Users\\SM2127\\anaconda3\\envs\\deep01\\lib\\site-packages\\IPython\\core\\interactiveshell.py\", line 2044, in showtraceback\n",
      "    stb = value._render_traceback_()\n",
      "AttributeError: 'TypeError' object has no attribute '_render_traceback_'\n",
      "\n",
      "During handling of the above exception, another exception occurred:\n",
      "\n",
      "Traceback (most recent call last):\n",
      "  File \"C:\\Users\\SM2127\\anaconda3\\envs\\deep01\\lib\\site-packages\\IPython\\core\\interactiveshell.py\", line 2895, in _run_cell\n",
      "    return runner(coro)\n",
      "  File \"C:\\Users\\SM2127\\anaconda3\\envs\\deep01\\lib\\site-packages\\IPython\\core\\async_helpers.py\", line 68, in _pseudo_sync_runner\n",
      "    coro.send(None)\n",
      "  File \"C:\\Users\\SM2127\\anaconda3\\envs\\deep01\\lib\\site-packages\\IPython\\core\\interactiveshell.py\", line 3072, in run_cell_async\n",
      "    interactivity=interactivity, compiler=compiler, result=result)\n",
      "  File \"C:\\Users\\SM2127\\anaconda3\\envs\\deep01\\lib\\site-packages\\IPython\\core\\interactiveshell.py\", line 3282, in run_ast_nodes\n",
      "    self.showtraceback()\n",
      "  File \"C:\\Users\\SM2127\\anaconda3\\envs\\deep01\\lib\\site-packages\\IPython\\core\\interactiveshell.py\", line 2047, in showtraceback\n",
      "    value, tb, tb_offset=tb_offset)\n",
      "  File \"C:\\Users\\SM2127\\anaconda3\\envs\\deep01\\lib\\site-packages\\IPython\\core\\ultratb.py\", line 1436, in structured_traceback\n",
      "    self, etype, value, tb, tb_offset, number_of_lines_of_context)\n",
      "  File \"C:\\Users\\SM2127\\anaconda3\\envs\\deep01\\lib\\site-packages\\IPython\\core\\ultratb.py\", line 1336, in structured_traceback\n",
      "    self, etype, value, tb, tb_offset, number_of_lines_of_context\n",
      "  File \"C:\\Users\\SM2127\\anaconda3\\envs\\deep01\\lib\\site-packages\\IPython\\core\\ultratb.py\", line 1211, in structured_traceback\n",
      "    chained_exceptions_tb_offset)\n",
      "  File \"C:\\Users\\SM2127\\anaconda3\\envs\\deep01\\lib\\site-packages\\IPython\\core\\ultratb.py\", line 1150, in format_exception_as_a_whole\n",
      "    last_unique, recursion_repeat = find_recursion(orig_etype, evalue, records)\n",
      "  File \"C:\\Users\\SM2127\\anaconda3\\envs\\deep01\\lib\\site-packages\\IPython\\core\\ultratb.py\", line 451, in find_recursion\n",
      "    return len(records), 0\n",
      "TypeError: object of type 'NoneType' has no len()\n",
      "\n",
      "During handling of the above exception, another exception occurred:\n",
      "\n",
      "Traceback (most recent call last):\n",
      "  File \"C:\\Users\\SM2127\\anaconda3\\envs\\deep01\\lib\\site-packages\\IPython\\core\\interactiveshell.py\", line 2044, in showtraceback\n",
      "    stb = value._render_traceback_()\n",
      "AttributeError: 'TypeError' object has no attribute '_render_traceback_'\n",
      "\n",
      "During handling of the above exception, another exception occurred:\n",
      "\n",
      "Traceback (most recent call last):\n",
      "  File \"C:\\Users\\SM2127\\anaconda3\\envs\\deep01\\lib\\site-packages\\IPython\\core\\ultratb.py\", line 1169, in get_records\n",
      "    return _fixed_getinnerframes(etb, number_of_lines_of_context, tb_offset)\n",
      "  File \"C:\\Users\\SM2127\\anaconda3\\envs\\deep01\\lib\\site-packages\\IPython\\core\\ultratb.py\", line 316, in wrapped\n",
      "    return f(*args, **kwargs)\n",
      "  File \"C:\\Users\\SM2127\\anaconda3\\envs\\deep01\\lib\\site-packages\\IPython\\core\\ultratb.py\", line 350, in _fixed_getinnerframes\n",
      "    records = fix_frame_records_filenames(inspect.getinnerframes(etb, context))\n",
      "  File \"C:\\Users\\SM2127\\anaconda3\\envs\\deep01\\lib\\inspect.py\", line 1490, in getinnerframes\n",
      "    frameinfo = (tb.tb_frame,) + getframeinfo(tb, context)\n",
      "  File \"C:\\Users\\SM2127\\anaconda3\\envs\\deep01\\lib\\inspect.py\", line 1448, in getframeinfo\n",
      "    filename = getsourcefile(frame) or getfile(frame)\n",
      "  File \"C:\\Users\\SM2127\\anaconda3\\envs\\deep01\\lib\\inspect.py\", line 696, in getsourcefile\n",
      "    if getattr(getmodule(object, filename), '__loader__', None) is not None:\n",
      "  File \"C:\\Users\\SM2127\\anaconda3\\envs\\deep01\\lib\\inspect.py\", line 733, in getmodule\n",
      "    if ismodule(module) and hasattr(module, '__file__'):\n",
      "  File \"C:\\Users\\SM2127\\anaconda3\\envs\\deep01\\lib\\site-packages\\tensorflow\\__init__.py\", line 50, in __getattr__\n",
      "    module = self._load()\n",
      "  File \"C:\\Users\\SM2127\\anaconda3\\envs\\deep01\\lib\\site-packages\\tensorflow\\__init__.py\", line 44, in _load\n",
      "    module = _importlib.import_module(self.__name__)\n",
      "  File \"C:\\Users\\SM2127\\anaconda3\\envs\\deep01\\lib\\importlib\\__init__.py\", line 126, in import_module\n",
      "    return _bootstrap._gcd_import(name[level:], package, level)\n",
      "  File \"<frozen importlib._bootstrap>\", line 994, in _gcd_import\n",
      "  File \"<frozen importlib._bootstrap>\", line 971, in _find_and_load\n",
      "  File \"<frozen importlib._bootstrap>\", line 953, in _find_and_load_unlocked\n",
      "ModuleNotFoundError: No module named 'tensorflow_core.estimator'\n"
     ]
    }
   ],
   "source": [
    "model.fit(X_data,y,epochs=100,batch_size=20,validation_split=0.25)"
   ]
  },
  {
   "cell_type": "code",
   "execution_count": null,
   "id": "609c4f20",
   "metadata": {},
   "outputs": [
    {
     "name": "stderr",
     "output_type": "stream",
     "text": [
      "ERROR:root:Internal Python error in the inspect module.\n",
      "Below is the traceback from this internal error.\n",
      "\n",
      "ERROR:root:Internal Python error in the inspect module.\n",
      "Below is the traceback from this internal error.\n",
      "\n",
      "ERROR:root:Internal Python error in the inspect module.\n",
      "Below is the traceback from this internal error.\n",
      "\n"
     ]
    },
    {
     "name": "stdout",
     "output_type": "stream",
     "text": [
      "Traceback (most recent call last):\n",
      "  File \"C:\\Users\\SM2127\\anaconda3\\envs\\deep01\\lib\\site-packages\\IPython\\core\\interactiveshell.py\", line 3343, in run_code\n",
      "    exec(code_obj, self.user_global_ns, self.user_ns)\n",
      "  File \"<ipython-input-20-4deb24720542>\", line 1, in <module>\n",
      "    model.evaluate(X_data,y)\n",
      "  File \"C:\\Users\\SM2127\\anaconda3\\envs\\deep01\\lib\\site-packages\\tensorflow_core\\python\\keras\\engine\\training.py\", line 930, in evaluate\n",
      "    use_multiprocessing=use_multiprocessing)\n",
      "  File \"C:\\Users\\SM2127\\anaconda3\\envs\\deep01\\lib\\site-packages\\tensorflow_core\\python\\keras\\engine\\training_v2.py\", line 490, in evaluate\n",
      "    use_multiprocessing=use_multiprocessing, **kwargs)\n",
      "  File \"C:\\Users\\SM2127\\anaconda3\\envs\\deep01\\lib\\site-packages\\tensorflow_core\\python\\keras\\engine\\training_v2.py\", line 426, in _model_iteration\n",
      "    use_multiprocessing=use_multiprocessing)\n",
      "  File \"C:\\Users\\SM2127\\anaconda3\\envs\\deep01\\lib\\site-packages\\tensorflow_core\\python\\keras\\engine\\training_v2.py\", line 636, in _process_inputs\n",
      "    adapter_cls = data_adapter.select_data_adapter(x, y)\n",
      "  File \"C:\\Users\\SM2127\\anaconda3\\envs\\deep01\\lib\\site-packages\\tensorflow_core\\python\\keras\\engine\\data_adapter.py\", line 998, in select_data_adapter\n",
      "    _type_name(x), _type_name(y)))\n",
      "ValueError: Failed to find data adapter that can handle input: (<class 'list'> containing values of types {'(<class \\'list\\'> containing values of types {\"<class \\'int\\'>\"})'}), <class 'pandas.core.frame.DataFrame'>\n",
      "\n",
      "During handling of the above exception, another exception occurred:\n",
      "\n",
      "Traceback (most recent call last):\n",
      "  File \"C:\\Users\\SM2127\\anaconda3\\envs\\deep01\\lib\\site-packages\\IPython\\core\\interactiveshell.py\", line 2044, in showtraceback\n",
      "    stb = value._render_traceback_()\n",
      "AttributeError: 'ValueError' object has no attribute '_render_traceback_'\n",
      "\n",
      "During handling of the above exception, another exception occurred:\n",
      "\n",
      "Traceback (most recent call last):\n",
      "  File \"C:\\Users\\SM2127\\anaconda3\\envs\\deep01\\lib\\site-packages\\IPython\\core\\ultratb.py\", line 1169, in get_records\n",
      "    return _fixed_getinnerframes(etb, number_of_lines_of_context, tb_offset)\n",
      "  File \"C:\\Users\\SM2127\\anaconda3\\envs\\deep01\\lib\\site-packages\\IPython\\core\\ultratb.py\", line 316, in wrapped\n",
      "    return f(*args, **kwargs)\n",
      "  File \"C:\\Users\\SM2127\\anaconda3\\envs\\deep01\\lib\\site-packages\\IPython\\core\\ultratb.py\", line 350, in _fixed_getinnerframes\n",
      "    records = fix_frame_records_filenames(inspect.getinnerframes(etb, context))\n",
      "  File \"C:\\Users\\SM2127\\anaconda3\\envs\\deep01\\lib\\inspect.py\", line 1490, in getinnerframes\n",
      "    frameinfo = (tb.tb_frame,) + getframeinfo(tb, context)\n",
      "  File \"C:\\Users\\SM2127\\anaconda3\\envs\\deep01\\lib\\inspect.py\", line 1448, in getframeinfo\n",
      "    filename = getsourcefile(frame) or getfile(frame)\n",
      "  File \"C:\\Users\\SM2127\\anaconda3\\envs\\deep01\\lib\\inspect.py\", line 696, in getsourcefile\n",
      "    if getattr(getmodule(object, filename), '__loader__', None) is not None:\n",
      "  File \"C:\\Users\\SM2127\\anaconda3\\envs\\deep01\\lib\\inspect.py\", line 733, in getmodule\n",
      "    if ismodule(module) and hasattr(module, '__file__'):\n",
      "  File \"C:\\Users\\SM2127\\anaconda3\\envs\\deep01\\lib\\site-packages\\tensorflow\\__init__.py\", line 50, in __getattr__\n",
      "    module = self._load()\n",
      "  File \"C:\\Users\\SM2127\\anaconda3\\envs\\deep01\\lib\\site-packages\\tensorflow\\__init__.py\", line 44, in _load\n",
      "    module = _importlib.import_module(self.__name__)\n",
      "  File \"C:\\Users\\SM2127\\anaconda3\\envs\\deep01\\lib\\importlib\\__init__.py\", line 126, in import_module\n",
      "    return _bootstrap._gcd_import(name[level:], package, level)\n",
      "  File \"<frozen importlib._bootstrap>\", line 994, in _gcd_import\n",
      "  File \"<frozen importlib._bootstrap>\", line 971, in _find_and_load\n",
      "  File \"<frozen importlib._bootstrap>\", line 953, in _find_and_load_unlocked\n",
      "ModuleNotFoundError: No module named 'tensorflow_core.estimator'\n",
      "Traceback (most recent call last):\n",
      "  File \"C:\\Users\\SM2127\\anaconda3\\envs\\deep01\\lib\\site-packages\\IPython\\core\\interactiveshell.py\", line 3343, in run_code\n",
      "    exec(code_obj, self.user_global_ns, self.user_ns)\n",
      "  File \"<ipython-input-20-4deb24720542>\", line 1, in <module>\n",
      "    model.evaluate(X_data,y)\n",
      "  File \"C:\\Users\\SM2127\\anaconda3\\envs\\deep01\\lib\\site-packages\\tensorflow_core\\python\\keras\\engine\\training.py\", line 930, in evaluate\n",
      "    use_multiprocessing=use_multiprocessing)\n",
      "  File \"C:\\Users\\SM2127\\anaconda3\\envs\\deep01\\lib\\site-packages\\tensorflow_core\\python\\keras\\engine\\training_v2.py\", line 490, in evaluate\n",
      "    use_multiprocessing=use_multiprocessing, **kwargs)\n",
      "  File \"C:\\Users\\SM2127\\anaconda3\\envs\\deep01\\lib\\site-packages\\tensorflow_core\\python\\keras\\engine\\training_v2.py\", line 426, in _model_iteration\n",
      "    use_multiprocessing=use_multiprocessing)\n",
      "  File \"C:\\Users\\SM2127\\anaconda3\\envs\\deep01\\lib\\site-packages\\tensorflow_core\\python\\keras\\engine\\training_v2.py\", line 636, in _process_inputs\n",
      "    adapter_cls = data_adapter.select_data_adapter(x, y)\n",
      "  File \"C:\\Users\\SM2127\\anaconda3\\envs\\deep01\\lib\\site-packages\\tensorflow_core\\python\\keras\\engine\\data_adapter.py\", line 998, in select_data_adapter\n",
      "    _type_name(x), _type_name(y)))\n",
      "ValueError: Failed to find data adapter that can handle input: (<class 'list'> containing values of types {'(<class \\'list\\'> containing values of types {\"<class \\'int\\'>\"})'}), <class 'pandas.core.frame.DataFrame'>\n",
      "\n",
      "During handling of the above exception, another exception occurred:\n",
      "\n",
      "Traceback (most recent call last):\n",
      "  File \"C:\\Users\\SM2127\\anaconda3\\envs\\deep01\\lib\\site-packages\\IPython\\core\\interactiveshell.py\", line 2044, in showtraceback\n",
      "    stb = value._render_traceback_()\n",
      "AttributeError: 'ValueError' object has no attribute '_render_traceback_'\n",
      "\n",
      "During handling of the above exception, another exception occurred:\n",
      "\n",
      "Traceback (most recent call last):\n",
      "  File \"C:\\Users\\SM2127\\anaconda3\\envs\\deep01\\lib\\site-packages\\IPython\\core\\interactiveshell.py\", line 3263, in run_ast_nodes\n",
      "    if (await self.run_code(code, result,  async_=asy)):\n",
      "  File \"C:\\Users\\SM2127\\anaconda3\\envs\\deep01\\lib\\site-packages\\IPython\\core\\interactiveshell.py\", line 3360, in run_code\n",
      "    self.showtraceback(running_compiled_code=True)\n",
      "  File \"C:\\Users\\SM2127\\anaconda3\\envs\\deep01\\lib\\site-packages\\IPython\\core\\interactiveshell.py\", line 2047, in showtraceback\n",
      "    value, tb, tb_offset=tb_offset)\n",
      "  File \"C:\\Users\\SM2127\\anaconda3\\envs\\deep01\\lib\\site-packages\\IPython\\core\\ultratb.py\", line 1436, in structured_traceback\n",
      "    self, etype, value, tb, tb_offset, number_of_lines_of_context)\n",
      "  File \"C:\\Users\\SM2127\\anaconda3\\envs\\deep01\\lib\\site-packages\\IPython\\core\\ultratb.py\", line 1336, in structured_traceback\n",
      "    self, etype, value, tb, tb_offset, number_of_lines_of_context\n",
      "  File \"C:\\Users\\SM2127\\anaconda3\\envs\\deep01\\lib\\site-packages\\IPython\\core\\ultratb.py\", line 1193, in structured_traceback\n",
      "    tb_offset)\n",
      "  File \"C:\\Users\\SM2127\\anaconda3\\envs\\deep01\\lib\\site-packages\\IPython\\core\\ultratb.py\", line 1150, in format_exception_as_a_whole\n",
      "    last_unique, recursion_repeat = find_recursion(orig_etype, evalue, records)\n",
      "  File \"C:\\Users\\SM2127\\anaconda3\\envs\\deep01\\lib\\site-packages\\IPython\\core\\ultratb.py\", line 451, in find_recursion\n",
      "    return len(records), 0\n",
      "TypeError: object of type 'NoneType' has no len()\n",
      "\n",
      "During handling of the above exception, another exception occurred:\n",
      "\n",
      "Traceback (most recent call last):\n",
      "  File \"C:\\Users\\SM2127\\anaconda3\\envs\\deep01\\lib\\site-packages\\IPython\\core\\interactiveshell.py\", line 2044, in showtraceback\n",
      "    stb = value._render_traceback_()\n",
      "AttributeError: 'TypeError' object has no attribute '_render_traceback_'\n",
      "\n",
      "During handling of the above exception, another exception occurred:\n",
      "\n",
      "Traceback (most recent call last):\n",
      "  File \"C:\\Users\\SM2127\\anaconda3\\envs\\deep01\\lib\\site-packages\\IPython\\core\\ultratb.py\", line 1169, in get_records\n",
      "    return _fixed_getinnerframes(etb, number_of_lines_of_context, tb_offset)\n",
      "  File \"C:\\Users\\SM2127\\anaconda3\\envs\\deep01\\lib\\site-packages\\IPython\\core\\ultratb.py\", line 316, in wrapped\n",
      "    return f(*args, **kwargs)\n",
      "  File \"C:\\Users\\SM2127\\anaconda3\\envs\\deep01\\lib\\site-packages\\IPython\\core\\ultratb.py\", line 350, in _fixed_getinnerframes\n",
      "    records = fix_frame_records_filenames(inspect.getinnerframes(etb, context))\n",
      "  File \"C:\\Users\\SM2127\\anaconda3\\envs\\deep01\\lib\\inspect.py\", line 1490, in getinnerframes\n",
      "    frameinfo = (tb.tb_frame,) + getframeinfo(tb, context)\n",
      "  File \"C:\\Users\\SM2127\\anaconda3\\envs\\deep01\\lib\\inspect.py\", line 1448, in getframeinfo\n",
      "    filename = getsourcefile(frame) or getfile(frame)\n",
      "  File \"C:\\Users\\SM2127\\anaconda3\\envs\\deep01\\lib\\inspect.py\", line 696, in getsourcefile\n",
      "    if getattr(getmodule(object, filename), '__loader__', None) is not None:\n",
      "  File \"C:\\Users\\SM2127\\anaconda3\\envs\\deep01\\lib\\inspect.py\", line 733, in getmodule\n",
      "    if ismodule(module) and hasattr(module, '__file__'):\n",
      "  File \"C:\\Users\\SM2127\\anaconda3\\envs\\deep01\\lib\\site-packages\\tensorflow\\__init__.py\", line 50, in __getattr__\n",
      "    module = self._load()\n",
      "  File \"C:\\Users\\SM2127\\anaconda3\\envs\\deep01\\lib\\site-packages\\tensorflow\\__init__.py\", line 44, in _load\n",
      "    module = _importlib.import_module(self.__name__)\n",
      "  File \"C:\\Users\\SM2127\\anaconda3\\envs\\deep01\\lib\\importlib\\__init__.py\", line 126, in import_module\n",
      "    return _bootstrap._gcd_import(name[level:], package, level)\n",
      "  File \"<frozen importlib._bootstrap>\", line 994, in _gcd_import\n",
      "  File \"<frozen importlib._bootstrap>\", line 971, in _find_and_load\n",
      "  File \"<frozen importlib._bootstrap>\", line 953, in _find_and_load_unlocked\n",
      "ModuleNotFoundError: No module named 'tensorflow_core.estimator'\n",
      "ERROR! Session/line number was not unique in database. History logging moved to new session 614\n",
      "Traceback (most recent call last):\n",
      "  File \"C:\\Users\\SM2127\\anaconda3\\envs\\deep01\\lib\\site-packages\\IPython\\core\\interactiveshell.py\", line 3343, in run_code\n",
      "    exec(code_obj, self.user_global_ns, self.user_ns)\n",
      "  File \"<ipython-input-20-4deb24720542>\", line 1, in <module>\n",
      "    model.evaluate(X_data,y)\n",
      "  File \"C:\\Users\\SM2127\\anaconda3\\envs\\deep01\\lib\\site-packages\\tensorflow_core\\python\\keras\\engine\\training.py\", line 930, in evaluate\n",
      "    use_multiprocessing=use_multiprocessing)\n",
      "  File \"C:\\Users\\SM2127\\anaconda3\\envs\\deep01\\lib\\site-packages\\tensorflow_core\\python\\keras\\engine\\training_v2.py\", line 490, in evaluate\n",
      "    use_multiprocessing=use_multiprocessing, **kwargs)\n",
      "  File \"C:\\Users\\SM2127\\anaconda3\\envs\\deep01\\lib\\site-packages\\tensorflow_core\\python\\keras\\engine\\training_v2.py\", line 426, in _model_iteration\n",
      "    use_multiprocessing=use_multiprocessing)\n",
      "  File \"C:\\Users\\SM2127\\anaconda3\\envs\\deep01\\lib\\site-packages\\tensorflow_core\\python\\keras\\engine\\training_v2.py\", line 636, in _process_inputs\n",
      "    adapter_cls = data_adapter.select_data_adapter(x, y)\n",
      "  File \"C:\\Users\\SM2127\\anaconda3\\envs\\deep01\\lib\\site-packages\\tensorflow_core\\python\\keras\\engine\\data_adapter.py\", line 998, in select_data_adapter\n",
      "    _type_name(x), _type_name(y)))\n",
      "ValueError: Failed to find data adapter that can handle input: (<class 'list'> containing values of types {'(<class \\'list\\'> containing values of types {\"<class \\'int\\'>\"})'}), <class 'pandas.core.frame.DataFrame'>\n",
      "\n",
      "During handling of the above exception, another exception occurred:\n",
      "\n",
      "Traceback (most recent call last):\n",
      "  File \"C:\\Users\\SM2127\\anaconda3\\envs\\deep01\\lib\\site-packages\\IPython\\core\\interactiveshell.py\", line 2044, in showtraceback\n",
      "    stb = value._render_traceback_()\n",
      "AttributeError: 'ValueError' object has no attribute '_render_traceback_'\n",
      "\n",
      "During handling of the above exception, another exception occurred:\n",
      "\n",
      "Traceback (most recent call last):\n",
      "  File \"C:\\Users\\SM2127\\anaconda3\\envs\\deep01\\lib\\site-packages\\IPython\\core\\interactiveshell.py\", line 3263, in run_ast_nodes\n",
      "    if (await self.run_code(code, result,  async_=asy)):\n",
      "  File \"C:\\Users\\SM2127\\anaconda3\\envs\\deep01\\lib\\site-packages\\IPython\\core\\interactiveshell.py\", line 3360, in run_code\n",
      "    self.showtraceback(running_compiled_code=True)\n",
      "  File \"C:\\Users\\SM2127\\anaconda3\\envs\\deep01\\lib\\site-packages\\IPython\\core\\interactiveshell.py\", line 2047, in showtraceback\n",
      "    value, tb, tb_offset=tb_offset)\n",
      "  File \"C:\\Users\\SM2127\\anaconda3\\envs\\deep01\\lib\\site-packages\\IPython\\core\\ultratb.py\", line 1436, in structured_traceback\n",
      "    self, etype, value, tb, tb_offset, number_of_lines_of_context)\n",
      "  File \"C:\\Users\\SM2127\\anaconda3\\envs\\deep01\\lib\\site-packages\\IPython\\core\\ultratb.py\", line 1336, in structured_traceback\n",
      "    self, etype, value, tb, tb_offset, number_of_lines_of_context\n",
      "  File \"C:\\Users\\SM2127\\anaconda3\\envs\\deep01\\lib\\site-packages\\IPython\\core\\ultratb.py\", line 1193, in structured_traceback\n",
      "    tb_offset)\n",
      "  File \"C:\\Users\\SM2127\\anaconda3\\envs\\deep01\\lib\\site-packages\\IPython\\core\\ultratb.py\", line 1150, in format_exception_as_a_whole\n",
      "    last_unique, recursion_repeat = find_recursion(orig_etype, evalue, records)\n",
      "  File \"C:\\Users\\SM2127\\anaconda3\\envs\\deep01\\lib\\site-packages\\IPython\\core\\ultratb.py\", line 451, in find_recursion\n",
      "    return len(records), 0\n",
      "TypeError: object of type 'NoneType' has no len()\n",
      "\n",
      "During handling of the above exception, another exception occurred:\n",
      "\n",
      "Traceback (most recent call last):\n",
      "  File \"C:\\Users\\SM2127\\anaconda3\\envs\\deep01\\lib\\site-packages\\IPython\\core\\interactiveshell.py\", line 2044, in showtraceback\n",
      "    stb = value._render_traceback_()\n",
      "AttributeError: 'TypeError' object has no attribute '_render_traceback_'\n",
      "\n",
      "During handling of the above exception, another exception occurred:\n",
      "\n",
      "Traceback (most recent call last):\n",
      "  File \"C:\\Users\\SM2127\\anaconda3\\envs\\deep01\\lib\\site-packages\\IPython\\core\\interactiveshell.py\", line 2895, in _run_cell\n",
      "    return runner(coro)\n",
      "  File \"C:\\Users\\SM2127\\anaconda3\\envs\\deep01\\lib\\site-packages\\IPython\\core\\async_helpers.py\", line 68, in _pseudo_sync_runner\n",
      "    coro.send(None)\n",
      "  File \"C:\\Users\\SM2127\\anaconda3\\envs\\deep01\\lib\\site-packages\\IPython\\core\\interactiveshell.py\", line 3072, in run_cell_async\n",
      "    interactivity=interactivity, compiler=compiler, result=result)\n",
      "  File \"C:\\Users\\SM2127\\anaconda3\\envs\\deep01\\lib\\site-packages\\IPython\\core\\interactiveshell.py\", line 3282, in run_ast_nodes\n",
      "    self.showtraceback()\n",
      "  File \"C:\\Users\\SM2127\\anaconda3\\envs\\deep01\\lib\\site-packages\\IPython\\core\\interactiveshell.py\", line 2047, in showtraceback\n",
      "    value, tb, tb_offset=tb_offset)\n",
      "  File \"C:\\Users\\SM2127\\anaconda3\\envs\\deep01\\lib\\site-packages\\IPython\\core\\ultratb.py\", line 1436, in structured_traceback\n",
      "    self, etype, value, tb, tb_offset, number_of_lines_of_context)\n",
      "  File \"C:\\Users\\SM2127\\anaconda3\\envs\\deep01\\lib\\site-packages\\IPython\\core\\ultratb.py\", line 1336, in structured_traceback\n",
      "    self, etype, value, tb, tb_offset, number_of_lines_of_context\n",
      "  File \"C:\\Users\\SM2127\\anaconda3\\envs\\deep01\\lib\\site-packages\\IPython\\core\\ultratb.py\", line 1211, in structured_traceback\n",
      "    chained_exceptions_tb_offset)\n",
      "  File \"C:\\Users\\SM2127\\anaconda3\\envs\\deep01\\lib\\site-packages\\IPython\\core\\ultratb.py\", line 1150, in format_exception_as_a_whole\n",
      "    last_unique, recursion_repeat = find_recursion(orig_etype, evalue, records)\n",
      "  File \"C:\\Users\\SM2127\\anaconda3\\envs\\deep01\\lib\\site-packages\\IPython\\core\\ultratb.py\", line 451, in find_recursion\n",
      "    return len(records), 0\n",
      "TypeError: object of type 'NoneType' has no len()\n",
      "\n",
      "During handling of the above exception, another exception occurred:\n",
      "\n",
      "Traceback (most recent call last):\n",
      "  File \"C:\\Users\\SM2127\\anaconda3\\envs\\deep01\\lib\\site-packages\\IPython\\core\\interactiveshell.py\", line 2044, in showtraceback\n",
      "    stb = value._render_traceback_()\n",
      "AttributeError: 'TypeError' object has no attribute '_render_traceback_'\n",
      "\n",
      "During handling of the above exception, another exception occurred:\n",
      "\n",
      "Traceback (most recent call last):\n",
      "  File \"C:\\Users\\SM2127\\anaconda3\\envs\\deep01\\lib\\site-packages\\IPython\\core\\ultratb.py\", line 1169, in get_records\n",
      "    return _fixed_getinnerframes(etb, number_of_lines_of_context, tb_offset)\n",
      "  File \"C:\\Users\\SM2127\\anaconda3\\envs\\deep01\\lib\\site-packages\\IPython\\core\\ultratb.py\", line 316, in wrapped\n",
      "    return f(*args, **kwargs)\n",
      "  File \"C:\\Users\\SM2127\\anaconda3\\envs\\deep01\\lib\\site-packages\\IPython\\core\\ultratb.py\", line 350, in _fixed_getinnerframes\n",
      "    records = fix_frame_records_filenames(inspect.getinnerframes(etb, context))\n",
      "  File \"C:\\Users\\SM2127\\anaconda3\\envs\\deep01\\lib\\inspect.py\", line 1490, in getinnerframes\n",
      "    frameinfo = (tb.tb_frame,) + getframeinfo(tb, context)\n",
      "  File \"C:\\Users\\SM2127\\anaconda3\\envs\\deep01\\lib\\inspect.py\", line 1448, in getframeinfo\n",
      "    filename = getsourcefile(frame) or getfile(frame)\n",
      "  File \"C:\\Users\\SM2127\\anaconda3\\envs\\deep01\\lib\\inspect.py\", line 696, in getsourcefile\n",
      "    if getattr(getmodule(object, filename), '__loader__', None) is not None:\n",
      "  File \"C:\\Users\\SM2127\\anaconda3\\envs\\deep01\\lib\\inspect.py\", line 733, in getmodule\n",
      "    if ismodule(module) and hasattr(module, '__file__'):\n",
      "  File \"C:\\Users\\SM2127\\anaconda3\\envs\\deep01\\lib\\site-packages\\tensorflow\\__init__.py\", line 50, in __getattr__\n",
      "    module = self._load()\n",
      "  File \"C:\\Users\\SM2127\\anaconda3\\envs\\deep01\\lib\\site-packages\\tensorflow\\__init__.py\", line 44, in _load\n",
      "    module = _importlib.import_module(self.__name__)\n",
      "  File \"C:\\Users\\SM2127\\anaconda3\\envs\\deep01\\lib\\importlib\\__init__.py\", line 126, in import_module\n",
      "    return _bootstrap._gcd_import(name[level:], package, level)\n",
      "  File \"<frozen importlib._bootstrap>\", line 994, in _gcd_import\n",
      "  File \"<frozen importlib._bootstrap>\", line 971, in _find_and_load\n",
      "  File \"<frozen importlib._bootstrap>\", line 953, in _find_and_load_unlocked\n",
      "ModuleNotFoundError: No module named 'tensorflow_core.estimator'\n"
     ]
    }
   ],
   "source": [
    "model.evaluate(X_data,y)"
   ]
  },
  {
   "cell_type": "code",
   "execution_count": null,
   "id": "a93c8edb",
   "metadata": {},
   "outputs": [],
   "source": [
    "model.predict([[0,1,0,0,0,1,0,1,1,1]])"
   ]
  }
 ],
 "metadata": {
  "kernelspec": {
   "display_name": "Python 3",
   "language": "python",
   "name": "python3"
  },
  "language_info": {
   "codemirror_mode": {
    "name": "ipython",
    "version": 3
   },
   "file_extension": ".py",
   "mimetype": "text/x-python",
   "name": "python",
   "nbconvert_exporter": "python",
   "pygments_lexer": "ipython3",
   "version": "3.6.13"
  }
 },
 "nbformat": 4,
 "nbformat_minor": 5
}
